<?xml version="1.0"?>
<robot xmlns:xacro="http://wiki.ros.org/xacro">
  <xacro:include filename="$(find fanuc_resources)/urdf/common_materials.xacro"/>

  <xacro:macro name="myrobot" params="prefix">
    <!-- links: main serial chain -->
    <link name="${prefix}base_link">
      <visual>
        <origin xyz="0 0 0.05" rpy="0 0 0"/>
        <geometry>
          <cylinder length="0.1" radius="0.03"/>
        </geometry>
        <xacro:material_fanuc_gray40 />
      </visual>
      <collision>
        <origin xyz="0 0 0.05" rpy="0 0 0"/>
        <geometry>
          <cylinder length="0.1" radius="0.03"/>
        </geometry>
      </collision>
    </link>
    <link name="${prefix}link_1">
      <visual>
        <origin xyz="0.05 0 0.0085" rpy="0 0 0"/>
        <geometry>
          <box size="0.2 0.04 0.017"/>
        </geometry>
        <xacro:material_fanuc_yellow />
      </visual>
      <collision>
        <origin xyz="0.05 0 0.0085" rpy="0 0 0"/>
        <geometry>
          <box size="0.2 0.04 0.017"/>
        </geometry>
      </collision>
    </link>
    <link name="${prefix}link_2">
      <visual>
        <origin xyz="0.03 0 0.0015" rpy="0 0 0"/>
        <geometry>
          <box size="0.16 0.04 0.003"/>
        </geometry>
        <xacro:material_fanuc_white />
      </visual>
      <collision>
        <origin xyz="0.03 0 0.0015" rpy="0 0 0"/>
        <geometry>
          <box size="0.16 0.04 0.003"/>
        </geometry>
      </collision>
    </link>
    <link name="${prefix}link_3">
      <visual>
        <origin xyz="0 0 0" rpy="0 0 0"/>
        <geometry>
          <cylinder length="0.1" radius="0.005"/>
        </geometry>
        <xacro:material_fanuc_green />
      </visual>
      <collision>
        <origin xyz="0 0 0" rpy="0 0 0"/>
        <geometry>
          <cylinder length="0.1" radius="0.005"/>
        </geometry>
      </collision>
    </link>
 
    <!-- joints: main serial chain -->
    <joint name="${prefix}joint_1" type="revolute">
      <origin xyz="0 0 0.1" rpy="0 0 0"/>
      <parent link="${prefix}base_link"/>
      <child link="${prefix}link_1"/>
      <axis xyz="0 0 1"/>
      <limit lower="-2.618" upper="2.618" effort="0" velocity="2.1"/>
    </joint>
    <joint name="${prefix}joint_2" type="revolute">
      <origin xyz="0.14 0 0.017" rpy="0 0 0"/>
      <parent link="${prefix}link_1"/>
      <child link="${prefix}link_2"/>
      <axis xyz="0 0 1"/>
      <limit lower="-2.618" upper="2.618" effort="0" velocity="2.1"/>
    </joint>
    <joint name="${prefix}joint_3" type="prismatic">
      <origin xyz="0.1 0 0" rpy="0 0 0"/>
      <parent link="${prefix}link_2"/>
      <child link="${prefix}link_3"/>
      <axis xyz="0 0 1"/>
      <limit lower="-0.05" upper="0.05" effort="0" velocity="0.03"/>
    </joint>
 
    <!-- ROS-Industrial 'base' frame: base_link to World Coordinates transform -->
    <!-- 
    <link name="${prefix}base" />
    <joint name="${prefix}base_link-base" type="fixed">
      <origin xyz="0 0 0.450" rpy="0 0 0"/>
      <parent link="${prefix}base_link"/>
      <child link="${prefix}base"/>
    </joint -->

    <!-- ROS-Industrial 'flange' frame: attachment point for EEF models -->
    <!-- link name="${prefix}flange" />
    <joint name="${prefix}joint_6-flange" type="fixed">
      <origin xyz="0 0 0" rpy="0 0 0" />
      <parent link="${prefix}link_6" />
      <child link="${prefix}flange" />
    </joint -->

    <!-- ROS-Industrial 'tool0' frame: all-zeros tool frame -->
    <link name="${prefix}tool0" />
    <joint name="${prefix}link_3-tool0" type="fixed">
      <!--origin xyz="0 0 0" rpy="${pi} ${-pi/2.0} 0" /-->
      <origin xyz="0 0 0" rpy="0 0 0" />
      <parent link="${prefix}link_3" />
      <child link="${prefix}tool0" />
    </joint>
  </xacro:macro>
</robot>
