<?xml version="1.0" ?>
<!-- =================================================================================== -->
<!-- |    This document was autogenerated by xacro from myrobot.xacro                  | -->
<!-- |    EDITING THIS FILE BY HAND IS NOT RECOMMENDED                                 | -->
<!-- =================================================================================== -->
<robot name="myrobot" xmlns:xacro="http://wiki.ros.org/xacro">
  <!-- links: main serial chain -->
  <link name="base_link">
    <visual>
      <origin rpy="0 0 0" xyz="0 0 0.05"/>
      <geometry>
        <cylinder length="0.1" radius="0.03"/>
      </geometry>
      <material name="">
        <color rgba="0.4 0.4 0.4 1.0"/>
      </material>
    </visual>
    <collision>
      <origin rpy="0 0 0" xyz="0 0 0.05"/>
      <geometry>
        <cylinder length="0.1" radius="0.03"/>
      </geometry>
    </collision>
  </link>
  <link name="link_1">
    <visual>
      <origin rpy="0 0 0" xyz="0.05 0 0.0085"/>
      <geometry>
        <box size="0.2 0.04 0.017"/>
      </geometry>
      <material name="">
        <color rgba="0.96 0.76 0.13 1.0"/>
      </material>
    </visual>
    <collision>
      <origin rpy="0 0 0" xyz="0.05 0 0.0085"/>
      <geometry>
        <box size="0.2 0.04 0.017"/>
      </geometry>
    </collision>
  </link>
  <link name="link_2">
    <visual>
      <origin rpy="0 0 0" xyz="0.03 0 0.0015"/>
      <geometry>
        <box size="0.16 0.04 0.003"/>
      </geometry>
      <material name="">
        <color rgba="0.86 0.85 0.81 1.0"/>
      </material>
    </visual>
    <collision>
      <origin rpy="0 0 0" xyz="0.03 0 0.0015"/>
      <geometry>
        <box size="0.16 0.04 0.003"/>
      </geometry>
    </collision>
  </link>
  <link name="link_3">
    <visual>
      <origin rpy="0 0 0" xyz="0 0 0"/>
      <geometry>
        <cylinder length="0.1" radius="0.005"/>
      </geometry>
      <material name="">
        <color rgba="0.0 0.607843137255 0.274509803922 1.0"/>
      </material>
    </visual>
    <collision>
      <origin rpy="0 0 0" xyz="0 0 0"/>
      <geometry>
        <cylinder length="0.1" radius="0.005"/>
      </geometry>
    </collision>
  </link>
  <!-- joints: main serial chain -->
  <joint name="joint_1" type="revolute">
    <origin rpy="0 0 0" xyz="0 0 0.1"/>
    <parent link="base_link"/>
    <child link="link_1"/>
    <axis xyz="0 0 1"/>
    <limit effort="0" lower="-2.618" upper="2.618" velocity="2.1"/>
  </joint>
  <joint name="joint_2" type="revolute">
    <origin rpy="0 0 0" xyz="0.14 0 0.017"/>
    <parent link="link_1"/>
    <child link="link_2"/>
    <axis xyz="0 0 1"/>
    <limit effort="0" lower="-2.618" upper="2.618" velocity="2.1"/>
  </joint>
  <joint name="joint_3" type="prismatic">
    <origin rpy="0 0 0" xyz="0.1 0 0"/>
    <parent link="link_2"/>
    <child link="link_3"/>
    <axis xyz="0 0 1"/>
    <limit effort="0" lower="-0.05" upper="0.05" velocity="0.03"/>
  </joint>
  <!-- ROS-Industrial 'base' frame: base_link to World Coordinates transform -->
  <!-- 
    <link name="${prefix}base" />
    <joint name="${prefix}base_link-base" type="fixed">
      <origin xyz="0 0 0.450" rpy="0 0 0"/>
      <parent link="${prefix}base_link"/>
      <child link="${prefix}base"/>
    </joint -->
  <!-- ROS-Industrial 'flange' frame: attachment point for EEF models -->
  <!-- link name="${prefix}flange" />
    <joint name="${prefix}joint_6-flange" type="fixed">
      <origin xyz="0 0 0" rpy="0 0 0" />
      <parent link="${prefix}link_6" />
      <child link="${prefix}flange" />
    </joint -->
  <!-- ROS-Industrial 'tool0' frame: all-zeros tool frame -->
  <link name="tool0"/>
  <joint name="link_3-tool0" type="fixed">
    <!--origin xyz="0 0 0" rpy="${pi} ${-pi/2.0} 0" /-->
    <origin rpy="0 0 0" xyz="0 0 0"/>
    <parent link="link_3"/>
    <child link="tool0"/>
  </joint>
  <link name="world"/>
  <link name="table">
    <visual>
      <origin rpy="0 0 0" xyz="0 0 0.01"/>
      <geometry>
        <box size="1.0 0.5 0.02"/>
      </geometry>
    </visual>
    <collision>
      <origin rpy="0 0 0" xyz="0 0 0.01"/>
      <geometry>
        <box size="1.0 1.0 0.02"/>
      </geometry>
    </collision>
  </link>
  <link name="camera_frame"/>
  <joint name="world_to_table" type="fixed">
    <parent link="world"/>
    <child link="table"/>
    <origin rpy="0 0 0" xyz="0 0 0"/>
  </joint>
  <joint name="world_to_camera" type="fixed">
    <parent link="world"/>
    <child link="camera_frame"/>
    <origin rpy="0 3.14159 0" xyz="0.1 0 0.3"/>
  </joint>
  <joint name="table_to_robot" type="fixed">
    <parent link="table"/>
    <child link="base_link"/>
    <origin rpy="0 0 0" xyz="0 0 0.02"/>
  </joint>
</robot>
