<?xml version="1.0"?>
<robot xmlns:xacro="http://wiki.ros.org/xacro">
  <xacro:include filename="$(find fanuc_resources)/urdf/common_materials.xacro"/>

  <xacro:macro name="myrobot" params="prefix">
    <!-- links: main serial chain -->
    <link name="${prefix}base_link">
      <visual>
        <origin xyz="0 0 0" rpy="0 0 0"/>
        <geometry>
          <mesh filename="package://myrobot_support/meshes/visual/base.stl"/>
        </geometry>
        <xacro:material_fanuc_gray40 />
      </visual>
      <collision>
        <origin xyz="0 0 0" rpy="0 0 0"/>
        <geometry>
          <mesh filename="package://myrobot_support/meshes/collision/base.stl"/>
        </geometry>
      </collision>
    </link>
    <link name="${prefix}link_1">
      <visual>
        <origin xyz="0 0 0" rpy="0 0 0"/>
        <geometry>
          <mesh filename="package://myrobot_support/meshes/visual/link1.stl"/>
        </geometry>
        <xacro:material_fanuc_yellow />
      </visual>
      <collision>
        <origin xyz="0 0 0" rpy="0 0 0"/>
        <geometry>
          <mesh filename="package://myrobot_support/meshes/collision/link1.stl"/>
        </geometry>
      </collision>
    </link>
    <link name="${prefix}link_2">
      <visual>
        <origin xyz="0 0 0" rpy="0 0 0"/>
        <geometry>
          <mesh filename="package://myrobot_support/meshes/visual/link2.stl"/>
        </geometry>
        <xacro:material_fanuc_white />
      </visual>
      <collision>
        <origin xyz="0 0 0" rpy="0 0 0"/>
        <geometry>
          <mesh filename="package://myrobot_support/meshes/collision/link2.stl"/>
        </geometry>
      </collision>
    </link>
    <link name="${prefix}link_3">
      <visual>
        <origin xyz="0 0 0" rpy="0 0 0"/>
        <geometry>
          <mesh filename="package://myrobot_support/meshes/visual/link3.stl"/>
        </geometry>
        <xacro:material_fanuc_green />
      </visual>
      <collision>
        <origin xyz="0 0 0" rpy="0 0 0"/>
        <geometry>
          <mesh filename="package://myrobot_support/meshes/collision/link3.stl"/>
        </geometry>
      </collision>
    </link>
 
    <!-- joints: main serial chain -->
    <joint name="${prefix}joint_1" type="prismatic">
      <origin xyz="0 0 0.005" rpy="0 0 0"/>
      <parent link="${prefix}base_link"/>
      <child link="${prefix}link_1"/>
      <axis xyz="0 0 1"/>
      <limit lower="0" upper="0.08" effort="0" velocity="0.004"/>
    </joint>
    <joint name="${prefix}joint_2" type="revolute">
      <origin xyz="0.039503 0 -0.005" rpy="0 0 0"/>
      <parent link="${prefix}link_1"/>
      <child link="${prefix}link_2"/>
      <axis xyz="0 0 1"/>
      <limit lower="-1.57" upper="1.49" effort="0" velocity="1.0472"/>
    </joint>
    <joint name="${prefix}joint_3" type="revolute">
      <origin xyz="0.07 0 0.006" rpy="0 0 0"/>
      <parent link="${prefix}link_2"/>
      <child link="${prefix}link_3"/>
      <axis xyz="0 0 1"/>
      <limit lower="-2.62" upper="2.62" effort="0" velocity="1.0472"/>
    </joint>
 
    <!-- ROS-Industrial 'base' frame: base_link to World Coordinates transform -->
    <!-- 
    <link name="${prefix}base" />
    <joint name="${prefix}base_link-base" type="fixed">
      <origin xyz="0 0 0.450" rpy="0 0 0"/>
      <parent link="${prefix}base_link"/>
      <child link="${prefix}base"/>
    </joint -->

    <!-- ROS-Industrial 'flange' frame: attachment point for EEF models -->
    <!-- link name="${prefix}flange" />
    <joint name="${prefix}joint_6-flange" type="fixed">
      <origin xyz="0 0 0" rpy="0 0 0" />
      <parent link="${prefix}link_6" />
      <child link="${prefix}flange" />
    </joint -->

    <!-- ROS-Industrial 'tool0' frame: all-zeros tool frame -->
    <link name="${prefix}tool0" />
    <joint name="${prefix}link_3-tool0" type="fixed">
      <!--origin xyz="0 0 0" rpy="${pi} ${-pi/2.0} 0" /-->
      <origin xyz="0 0 0" rpy="0 0 0" />
      <parent link="${prefix}link_3" />
      <child link="${prefix}tool0" />
    </joint>
  </xacro:macro>
</robot>
