<?xml version="1.0" ?>
<!-- =================================================================================== -->
<!-- |    This document was autogenerated by xacro from myrobot.xacro                  | -->
<!-- |    EDITING THIS FILE BY HAND IS NOT RECOMMENDED                                 | -->
<!-- =================================================================================== -->
<robot name="myrobot" xmlns:xacro="http://wiki.ros.org/xacro">
  <!-- links: main serial chain -->
  <link name="base_link">
    <visual>
      <origin rpy="0 0 0" xyz="0 0 0"/>
      <geometry>
        <mesh filename="package://myrobot_support/meshes/visual/base.stl"/>
      </geometry>
      <material name="">
        <color rgba="0.4 0.4 0.4 1.0"/>
      </material>
    </visual>
    <collision>
      <origin rpy="0 0 0" xyz="0 0 0"/>
      <geometry>
        <mesh filename="package://myrobot_support/meshes/collision/base.stl"/>
      </geometry>
    </collision>
  </link>
  <link name="link_1">
    <visual>
      <origin rpy="0 0 0" xyz="0 0 0"/>
      <geometry>
        <mesh filename="package://myrobot_support/meshes/visual/link1.stl"/>
      </geometry>
      <material name="">
        <color rgba="0.96 0.76 0.13 1.0"/>
      </material>
    </visual>
    <collision>
      <origin rpy="0 0 0" xyz="0 0 0"/>
      <geometry>
        <mesh filename="package://myrobot_support/meshes/collision/link1.stl"/>
      </geometry>
    </collision>
  </link>
  <link name="link_2">
    <visual>
      <origin rpy="0 0 0" xyz="0 0 0"/>
      <geometry>
        <mesh filename="package://myrobot_support/meshes/visual/link2.stl"/>
      </geometry>
      <material name="">
        <color rgba="0.86 0.85 0.81 1.0"/>
      </material>
    </visual>
    <collision>
      <origin rpy="0 0 0" xyz="0 0 0"/>
      <geometry>
        <mesh filename="package://myrobot_support/meshes/collision/link2.stl"/>
      </geometry>
    </collision>
  </link>
  <link name="link_3">
    <visual>
      <origin rpy="0 0 0" xyz="0 0 0"/>
      <geometry>
        <mesh filename="package://myrobot_support/meshes/visual/link3.stl"/>
      </geometry>
      <material name="">
        <color rgba="0.0 0.607843137255 0.274509803922 1.0"/>
      </material>
    </visual>
    <collision>
      <origin rpy="0 0 0" xyz="0 0 0"/>
      <geometry>
        <mesh filename="package://myrobot_support/meshes/collision/link3.stl"/>
      </geometry>
    </collision>
  </link>
  <!-- joints: main serial chain -->
  <joint name="joint_1" type="prismatic">
    <origin rpy="0 0 0" xyz="0 0 0.005"/>
    <parent link="base_link"/>
    <child link="link_1"/>
    <axis xyz="0 0 1"/>
    <limit effort="0" lower="0" upper="0.05" velocity="0.004"/>
  </joint>
  <joint name="joint_2" type="revolute">
    <origin rpy="0 0 0" xyz="0.039503 0 -0.005"/>
    <parent link="link_1"/>
    <child link="link_2"/>
    <axis xyz="0 0 1"/>
    <limit effort="0" lower="-1.57" upper="1.5" velocity="1.0472"/>
  </joint>
  <joint name="joint_3" type="revolute">
    <origin rpy="0 0 0" xyz="0.07 0 0.006"/>
    <parent link="link_2"/>
    <child link="link_3"/>
    <axis xyz="0 0 1"/>
    <limit effort="0" lower="-2.62" upper="2.62" velocity="1.0472"/>
  </joint>
  
  <!--
  <link name="world">
    <visual>
      <geometry>
        <box size="0.01 0.01 0.5"/>
      </geometry>
    </visual>  
  </link>
  <link name="camera_frame">
    <visual>
      <geometry>
        <box size="0.05 0.05 0.01"/>
      </geometry>
    </visual>  
  </link>  -->
  
  <link name="world"/>
  
  <link name="table">
    <visual>
      <geometry>
        <box size="0.12 0.12 0.02"/>
      </geometry>
      <material name="">
        <color rgba="0.0 0.607843137255 0.274509803922 1.0"/>
      </material>      
    </visual>
    <collision>
      <geometry>
        <box size="0.12 0.12 0.02"/>
      </geometry>
    </collision>
  </link>
  <link name="camera_frame"/>

  <joint name="world_to_table" type="fixed">
    <parent link="world"/>
    <child link="table"/>
    <origin xyz="0 0 0" rpy="0 0 0"/>
  </joint>

  <joint name="world_to_camera" type="fixed">
    <parent link="world"/>
    <child link="camera_frame"/>
    <origin xyz="0 0 0.2" rpy="0 3.14159 0"/>
  </joint>
  <joint name="table_to_robot" type="fixed">
    <parent link="table"/>
    <child link="base_link"/>
    <origin xyz="0 0 0.05" rpy="0 0 0"/>
  </joint>    
  
  <!-- ROS-Industrial 'base' frame: base_link to Fanuc World Coordinates transform -->
  <!-- 
    <link name="${prefix}base" />
    <joint name="${prefix}base_link-base" type="fixed">
      <origin xyz="0 0 0.450" rpy="0 0 0"/>
      <parent link="${prefix}base_link"/>
      <child link="${prefix}base"/>
    </joint -->
  <!-- ROS-Industrial 'flange' frame: attachment point for EEF models -->
  <!-- link name="${prefix}flange" />
    <joint name="${prefix}joint_6-flange" type="fixed">
      <origin xyz="0 0 0" rpy="0 0 0" />
      <parent link="${prefix}link_6" />
      <child link="${prefix}flange" />
    </joint -->
    
    <!-- ROS-Industrial 'tool0' frame: all-zeros tool frame -->
    <link name="tool0" />
    <joint name="link_3-tool0" type="fixed">
      <!--origin xyz="0 0 0" rpy="${pi} ${-pi/2.0} 0" /-->
      <origin xyz="0.05 0 0" rpy="0 0 0" />
      <parent link="link_3" />
      <child link="tool0" />
    </joint>
</robot>
